Workbook

Sheet Overview
A1: BAForge Workshop Input Templates
A2: One structured capture template per methodology task. Print, fill in workshops, then enter data into BAForge.
A4: TEMPLATE INDEX
A5: Task | B5: Title | C5: Phase | D5: Step | E5: Category | F5: Tool | G5: Duration | H5: Workshop Type
A6: T01 | B6: Define Project Scope | C6: Plan | D6: Setup | E6: Scoping | F6: BAForge Agent > Setup | G6: 2 hours | H6: Kickoff meeting
A7: T02 | B7: Assess Current State | C7: Plan | D7: Discovery | E7: Analysis | F7: BAForge Agent > Discovery | G7: 3-5 days | H7: Stakeholder interviews (1h each)
A8: T03 | B8: Design Target State | C8: Plan | D8: Design | E8: Specification | F8: BAForge Agent > Design | G8: Half day | H8: Design workshop (half-day)
A9: T04 | B9: Run Compliance Assessment | C9: Plan | D9: Discovery | E9: Quality | F9: BAForge Agent > Discovery (Compliance) | G9: 2-3 hours | H9: Compliance review with legal/regulatory team
A10: T05 | B10: Define Actors & Permissions | C10: Define | D10: Business Logic | E10: Specification | F10: BAForge Agent > Business Logic > Actors | G10: 2 hours | H10: Actor mapping session
A11: T06 | B11: Define Business Rules | C11: Define | D11: Business Logic | E11: Specification | F11: BAForge Agent > Business Logic > Rules | G11: Half day | H11: Rules elicitation with domain experts
A12: T07 | B12: Map Workflows | C12: Define | D12: Business Logic | E12: Specification | F12: BAForge Agent > Business Logic > Workflows | G12: Half day per workflow | H12: Process mapping with end users
A13: T08 | B13: Build Data Model | C13: Define | D13: Data Model | E13: Data Modelling | F13: BAForge Agent > Data Model | G13: 1-2 days per entity | H13: Data mapping with architects + source system owners
A14: T10 | B14: Specify API Endpoints | C14: Define | D14: API Specs | E14: Integration | F14: BAForge Agent > API Specs | G14: Half day | H14: API review with integration team
A15: T11 | B15: Define Technical Specifications | C15: Execute | D15: Build | E15: Specification | F15: BAForge Agent > Build | G15: Half day | H15: Technical design review
A16: T12 | B16: Plan Transition & Handover | C16: Execute | D16: Deploy | E16: Delivery | F16: BAForge Agent > Deploy | G16: Half day | H16: Transition planning with PMO + change management
... A20: T31 | B20: Estimate Data Volumes | C20: Govern | D20: NFRs & Sizing | E20: Governance | F20: BAForge Agent > NFRs & Sizing > Data Volumes | G20: 2-3 hours | H20: Sizing session with DBAs + architects
A23: EXPORT SHEETS — BAForge Import Guide
A24: Export Sheet | B24: Source Workshop | C24: BAForge Layout | D24: Import Target | E24: Method | F24: Rows
A25: Export Actors | B25: T05 Actors | C25: actors | D25: Agent > Business Logic > Actors > Import CSV | G25: Formula
A26: Export Rules | B26: T06 Rules | C26: rules | D26: Agent > Business Logic > Rules > Import CSV | G26: Formula
A27: Export Workflows | B27: T07 Workflows | C27: workflows | D27: Agent > Business Logic > Workflows > Import CSV | G27: Formula
A28: Export Fields | B28: T08 DataModel | C28: fields | D28: Agent > Data Model > (entity) > Import CSV: Fields | G28: Formula
A29: Export Endpoints | B29: T09 APIs | C29: apiEndpoints | D29: Agent > API Specs > Import CSV | G29: Formula
A30: Export Requirements | B30: T03 To-Be | C30: traceability | D30: Agent > Traceability > Import CSV | G30: Formula
A31: Export Questions | B31: Multiple | C31: openQuestions | D31: Agent > Open Items > Questions > Import CSV | G31: Manual
A32: Export Glossary | B32: Multiple | C32: glossary | D32: Agent > Open Items > Glossary > Import CSV | G32: Manual
A33: Export Risks | B33: T13 Risks | C33: risks | D33: Agent > Governance > Risks (manual entry) | G33: Formula
A34: Export NFRs | B34: T14 NFRs | C34: nfrs | D34: Agent > NFRs & Sizing > NFRs (manual entry) | G34: Formula
A35: Export Volumes | B35: T15 Volumes | C35: dataVolumes | D35: Agent > NFRs & Sizing > Data Volumes (manual entry) | G35: Formula

Sheet T01 Scope
A1: T01 Define Project Scope
A2: Stage: Plan | Step: Setup | Category: Scoping | Tool: BAForge Agent > Setup
A3: Goal: Establish project identity, boundaries, methodology, and key parameters
A5: WORKSHOP LOGISTICS
A6: Date | E6: Duration | F6: 2 hours
A7: Facilitator | E7: Location / Link
A8: Workshop Type | B8: Kickoff meeting | E8: Project
A10: ATTENDEES
A11: # | B11: Name | C11: Role | D11: Organisation | E11: Email | F11: Present (Y/N) | G11: Action Owner | H11: Notes
A12: 1
A13: 2
A14: 3
A15: 4
A16: 5
A17: 6
A19: PREPARATION CHECKLIST
A20: # | B20: Input Required | C20: Source | D20: Status | E20: Owner | F20: Notes
A21: 1 | B21: Project brief or RFP | D21: Sponsor
A22: 2 | B22: Organisational chart | D22: HR / PMO
A23: 3 | B23: Budget approval document | D23: Finance
A24: 4 | B24: Strategic roadmap | D24: CTO office
A26: WORKSHOP CAPTURE
A27: Project identity
A28: Project Name | B28: e.g. IMMOGEST Financial Hub Integration
A29: Client / Organisation | B29: e.g. EEAS — European External Action Service
A30: Sponsor Name & Role
A31: Project Manager
A33: Project parameters
A34: Industry / Domain | B34: EU Institutions / Banking / Insurance / Telecom / Energy / Public Sector / Healthcare
A35: Transformation Type | B35: System Migration / Digital Transformation / Process Reengineering / Regulatory / BI / ERP / Cloud
A36: Methodology | B36: Agile / Waterfall / Hybrid / SAFe / Lean Six Sigma / PRINCE2
A37: Timeline | B37: e.g. Q3 2026 — Q1 2027
A38: Budget Range | B38: e.g. 500K — 1M EUR
A40: Scope boundaries
A41: In Scope | B41: What is included in this project...
A42: Out of Scope | B42: What is explicitly excluded...
A43: Key Constraints | B43: Hard deadlines, fixed tech, regulatory mandates...
A44: Dependencies on Other Projects | B44: Projects that must deliver before or alongside this one...
A47: EXPECTED OUTPUTS
A48: # | B48: Output | C48: Status | D48: Owner | E48: Uploaded to BAForge | F48: Notes
...

Sheet T02 As-Is
A1: T02 Assess Current State
A2: Stage: Plan | Step: Discovery | Category: Analysis | Tool: BAForge Agent > Discovery
A3: Goal: Document As-Is systems, processes, pain points, and stakeholder landscape
A5: WORKSHOP LOGISTICS
A6: Date | E6: Duration | F6: 3-5 days
A7: Facilitator | E7: Location / Link
A8: Workshop Type | B8: Stakeholder interviews (1h each) | E8: Project
A10: ATTENDEES
A11: # | B11: Name | C11: Role | D11: Organisation | E11: Email | F11: Present (Y/N) | G11: Action Owner | H11: Notes
A12: 1
A13: 2
A14: 3
A15: 4
A16: 5
A17: 6
A19: PREPARATION CHECKLIST
A20: # | B20: Input Required | C20: Source | D20: Status | E20: Owner | F20: Notes
A21: 1 | B21: Existing system documentation | D21: IT / System owners
A22: 2 | B22: Process maps | D22: Process owners
A23: 3 | B23: Organisation chart | D23: HR
A24: 4 | B24: User feedback / support tickets | D24: Service desk
A26: WORKSHOP CAPTURE
A27: Stakeholder register
A28: # | B28: Name | C28: Role | D28: Department | E28: Influence (H/M/L) | F28: Interest (H/M/L) | G28: Engagement Strategy | H28: Notes
A29: 1 | B29: Maria Gonzalez | C29: Head of Real Estate | D29: HQ Admin | E29: High | F29: High | G29: Bi-weekly steering | H29: Project sponsor
A41: Current systems inventory
A42: # | B42: System Name | C42: Vendor / Type | D42: Purpose | E42: Users | F42: Data Volumes | G42: Integration Points | H42: Pain Points
A43: 1 | B43: IMMOGEST | C43: Java / Oracle | D43: Real estate management | E43: 500+ | F43: ~5K contracts | G43: ABAC, ARES, EU Login | H43: ABAC decommission
A53: Pain points (prioritised)
A54: # | B54: Pain Point | C54: Impact Area | D54: Severity (1-5) | E54: Frequency | F54: Affected Users | G54: Current Workaround | H54: Root Cause
A66: As-Is narrative
A67: Current state description | B67: Describe the current systems, processes, and how they work together...
A68: Data landscape | B68: Data sources, volumes, quality issues, integration patterns...
A69: Regulatory context | B69: Which regulations apply, current compliance status...
A72: EXPECTED OUTPUTS
A73: # | B73: Output | C73: Status | D73: Owner | E73: Uploaded to BAForge | F73: Notes
A74: 1 | B74: Stakeholder register with roles and influence
A75: 2 | B75: As-Is situation narrative
A76: 3 | B76: Pain points list (prioritised)
A77: 4 | B77: Existing systems inventory
...

Sheet T03 To-Be
A1: T03 Design Target State
A2: Stage: Plan | Step: Design | Category: Specification | Tool: BAForge Agent > Design
A3: Goal: Define To-Be architecture, requirements, KPIs, and constraints
A5: WORKSHOP LOGISTICS
A6: Date | E6: Duration | F6: Half day
A7: Facilitator | E7: Location / Link
A8: Workshop Type | B8: Design workshop (half-day) | E8: Project
A10: ATTENDEES
A11: # | B11: Name | C11: Role | D11: Organisation | E11: Email | F11: Present (Y/N) | G11: Action Owner | H11: Notes
A12: 1
A13: 2
A14: 3
A15: 4
A16: 5
A17: 6
A19: PREPARATION CHECKLIST
A20: # | B20: Input Required | C20: Source | D20: Status | E20: Owner | F20: Notes
A21: 1 | B21: As-Is documentation (T02) | D21: BA Lead (T02)
A22: 2 | B22: Business strategy | D22: Strategy team
A23: 3 | B23: Regulatory requirements | D23: Legal / Compliance
A24: 4 | B24: Technology roadmap | D24: CTO / Architecture
A26: WORKSHOP CAPTURE
A27: To-Be vision
A28: Target state description | B28: Describe the desired end state — architecture, processes, user experience...
A29: Key changes from As-Is | B29: What specifically changes between current and target state...
A31: High-level requirements
A32: REQ ID | B32: Requirement | C32: Priority | D32: Acceptance Criteria | E32: Regulatory Ref | F32: Source | G32: MoSCoW | H32: Notes
A33: REQ-001 | B33: System shall enforce valid contract status transitions | C33: Critical | D33: Only DRAFT>IN_FORCE>EXPIRED>ARCHIVED allowed | E33: EU Financial Reg | F33: Design workshop | G33: Must
A47: KPIs and success criteria
A48: # | B48: KPI | C48: Current Baseline | D48: Target Value | E48: Measurement Method | F48: Measurement Frequency | G48: Owner
A56: User stories
A57: US ID | B57: As a [role] | C57: I want [capability] | D57: So that [benefit] | E57: Linked REQ | F57: Priority | G57: Acceptance Criteria
A70: EXPECTED OUTPUTS
A71: # | B71: Output | C71: Status | D71: Owner | E71: Uploaded to BAForge | F71: Notes
A72: 1 | B72: To-Be vision document
A73: 2 | B73: High-level requirements (REQ-XXX)
A74: 3 | B74: Success KPIs
A75: 4 | B75: Integration requirements
A76: 5 | B76: Key user stories
A77: 6 | B77: Design constraints
...

Sheet T04 Compliance
A1: T04 Run Compliance Assessment
A2: Stage: Plan | Step: Discovery | Category: Quality | Tool: BAForge Agent > Discovery (Compliance)
A3: Goal: Identify applicable regulations and assess compliance readiness per domain
A5: WORKSHOP LOGISTICS
A6: Date | E6: Duration | F6: 2-3 hours
A7: Facilitator | E7: Location / Link
A8: Workshop Type | B8: Compliance review with legal/regulatory team | E8: Project
A10: ATTENDEES
A11: # | B11: Name | C11: Role | D11: Organisation | E11: Email | F11: Present (Y/N) | G11: Action Owner | H11: Notes
A12: 1
A13: 2
A14: 3
A15: 4
A16: 5
A17: 6
A19: PREPARATION CHECKLIST
A20: # | B20: Input Required | C20: Source | D20: Status | E20: Owner | F20: Notes
A21: 1 | B21: Domain selection (T01) | D21: T01 output
A22: 2 | B22: Regulatory framework documents | D22: Legal team
A23: 3 | B23: Existing compliance reports | D23: Compliance team
A24: 4 | B24: Audit findings | D24: Internal audit
A26: WORKSHOP CAPTURE
A27: Regulatory applicability assessment
A28: Regulation | B28: Applicable (Y/N) | C28: Critical | D28: Key Requirements | E28: Current Status | F28: Gap | G28: Remediation | H28: Owner
A29: EU Financial Regulation | B29: Y | C29: Critical | D29: Budget implementation, commitment workflows, audit trail | E29: Partial | F29: SUMMA alignment needed | G29: Map ABAC workflows to SUMMA | H29: Finance Unit
A41: Compliance checks
A42: # | B42: Item | C42: Status | D42: Evidence / Notes
A43: 1 | B43: Data Protection Impact Assessment (DPIA) completed
A44: 2 | B44: Data Processing Register updated
A45: 3 | B45: Consent mechanisms in place
A46: 4 | B46: Breach notification procedure defined
A47: 5 | B47: Access control matrix documented
A48: 6 | B48: Audit trail requirements specified
A49: 7 | B49: Incident response plan updated
A50: 8 | B50: Business continuity plan reviewed
A51: 9 | B51: Security classification applied
A52: 10 | B52: Cross-border transfer assessment done
A55: EXPECTED OUTPUTS
A56: # | B56: Output | C56: Status | D56: Owner | E56: Uploaded to BAForge | F56: Notes
A57: 1 | B57: Compliance checklist (domain-specific)
...

Sheet T05 Actors
A1: T05 Define Actors & Permissions
A2: Stage: Define | Step: Business Logic | Category: Specification | Tool: BAForge Agent > Business Logic > Actors
A3: Goal: Catalogue all system actors with types, CRUD permissions, and data access scope
A5: WORKSHOP LOGISTICS
A6: Date | E6: Duration | F6: 2 hours
A7: Facilitator | E7: Location / Link
A8: Workshop Type | B8: Actor mapping session | E8: Project
A10: ATTENDEES
A11: # | B11: Name | C11: Role | D11: Organisation | E11: Email | F11: Present (Y/N) | G11: Action Owner | H11: Notes
A12: 1
A13: 2
A14: 3
A15: 4
A16: 5
A17: 6
A19: PREPARATION CHECKLIST
A20: # | B20: Input Required | C20: Source | D20: Status | E20: Owner | F20: Notes
A21: 1 | B21: Stakeholder register (T02) | D21: T02 output
A22: 2 | B22: System access matrix | D22: IT Security
A23: 3 | B23: Role definitions | D23: HR / IAM
A24: 4 | B24: Security policy | D24: Security team
A26: WORKSHOP CAPTURE
A27: Actor catalogue
A28: Actor ID | B28: Name | C28: Type | D28: Description | E28: C | F28: R | G28: U | H28: D
A29: AC001 | B29: HQ User Admin | C29: Primary Actor | D29: Full admin rights across all delegations | E29: Y | F29: Y | G29: Y | H29: Y
A30: AC005 | B30: Financial Hub | C30: System Actor | D30: External financial system providing LCK/LEF/BAF | F30: Y
A42: Permission scope
A43: Actor ID | B43: Data Scope | C43: Geographic Scope | D43: Time Restrictions | E43: Delegation Rules | F43: Escalation Path
A54: EXPECTED OUTPUTS
A55: # | B55: Output | C55: Status | D55: Owner | E55: Uploaded to BAForge | F55: Notes
A56: 1 | B56: Actor catalogue (AC001-ACnnn)
A57: 2 | B57: Actor types
A58: 3 | B58: CRUD matrix per actor
A59: 4 | B59: Permission scope per actor
A62: ACTIONS & FOLLOW-UPS
A63: # | B63: Action | C63: Owner | D63: Due Date | E63: Priority | F63: Status | G63: Linked Task | H63: Notes
A74: CONNECTED TASKS (cross-reference)
A75: T02 | B75: Stakeholders become actors
A76: T06 | B76: Actors participate in workflows
A77: T07 | B77: Actors own workflow steps
...

Sheet T06 Rules
A1: T06 Define Business Rules
A2: Stage: Define | Step: Business Logic | Category: Specification | Tool: BAForge Agent > Business Logic > Rules
A3: Goal: Capture all IF/THEN/ELSE business rules with categories, priorities, and regulatory sources
A5: WORKSHOP LOGISTICS
A6: Date | E6: Duration | F6: Half day
A7: Facilitator | E7: Location / Link
A8: Workshop Type | B8: Rules elicitation with domain experts | E8: Project
A10: ATTENDEES
A11: # | B11: Name | C11: Role | D11: Organisation | E11: Email | F11: Present (Y/N) | G11: Action Owner | H11: Notes
A12: 1
A13: 2
A14: 3
A15: 4
A16: 5
A17: 6
A19: PREPARATION CHECKLIST
A20: # | B20: Input Required | C20: Source | D20: Status | E20: Owner | F20: Notes
A21: 1 | B21: Requirements (T03) | D21: T03 output
A22: 2 | B22: Compliance checklist (T04) | D22: T04 output
A23: 3 | B23: Existing business rules | D23: Business owners
A24: 4 | B24: Regulatory texts | D24: Legal
A26: WORKSHOP CAPTURE
A27: Business rules catalogue
A28: BR ID | B28: Name | C28: Category | D28: Priority | E28: IF (condition) | F28: THEN (action) | G28: ELSE (exception) | H28: Source
A29: BR053 | B29: LCK Format Validation | C29: Validation | D29: Critical | E29: LCK reference entered | F29: Validate format EAS.XXXXXX | G29: Show error per BR064 | H29: FH Spec
A30: BR055 | B30: BAF Validation | C30: Compliance | D30: Critical | E30: Bank account retrieved | F30: Check IBAN + status + earlyWarning + expiry | G30: Block contract creation | H30: FH Spec
A47: Rule-to-requirement mapping
A48: BR ID | B48: Linked REQ | C48: Linked Workflow Step | D48: Linked Field(s) | E48: Regulatory Reference | F48: Audit Impact
A61: EXPECTED OUTPUTS
A62: # | B62: Output | C62: Status | D62: Owner | E62: Uploaded to BAForge | F62: Notes
A63: 1 | B63: Business rules catalogue (BR001-BRnnn)
A64: 2 | B64: IF/THEN/ELSE per rule
A65: 3 | B65: Category and priority
A66: 4 | B66: Source reference and linked REQ
A69: ACTIONS & FOLLOW-UPS
A70: # | B70: Action | C70: Owner | D70: Due Date | E70: Priority | F70: Status | G70: Linked Task | H70: Notes
A81: CONNECTED TASKS (cross-reference)
A82: T03 | B82: Requirements drive rule creation
A83: T04 | B83: Compliance checks become rules
A84: T07 | B84: Rules are triggered within workflows
...

Sheet T07 Workflows
A1: T07 Map Workflows
A2: Stage: Define | Step: Business Logic | Category: Specification | Tool: BAForge Agent > Business Logic > Workflows
A3: Goal: Document step-by-step workflows with actors, triggers, decisions, and outputs
A5: WORKSHOP LOGISTICS
A6: Date | E6: Duration | F6: Half day per workflow
A7: Facilitator | E7: Location / Link
A8: Workshop Type | B8: Process mapping with end users | E8: Project
A10: ATTENDEES
A11: # | B11: Name | C11: Role | D11: Organisation | E11: Email | F11: Present (Y/N) | G11: Action Owner | H11: Notes
A12: 1
A13: 2
A14: 3
A15: 4
A16: 5
A17: 6
A19: PREPARATION CHECKLIST
A20: # | B20: Input Required | C20: Source | D20: Status | E20: Owner | F20: Notes
A21: 1 | B21: Actor catalogue (T05) | D21: T05 output
A22: 2 | B22: Business rules (T06) | D22: T06 output
A23: 3 | B23: As-Is process maps (T02) | D23: T02 output
A25: WORKSHOP CAPTURE
A26: Workflow header
A27: Workflow ID | B27: WF001
A28: Workflow Name | B28: e.g. Contract Creation
A29: Trigger Event | B29: What starts this workflow?
A30: Owner (Actor) | B30: Which actor owns this process?
A31: Pre-conditions | B31: What must be true before this workflow can start?
A32: Post-conditions | B32: What is true after this workflow completes?
A34: Workflow steps
A35: Step # | B35: Type | C35: Description | D35: Actor | E35: Input | F35: Output | G35: Business Rule | H35: Decision Branch
A36: 1 | B36: Start | C36: Navigate to Building > Contracts | D36: AC004 | E36: Building ID | F36: Form displayed
A37: 2 | B37: Action | C37: Enter LCK reference (EAS.XXXXXX) | D37: AC004 | E37: LCK value | F37: LCK entered | G37: BR053
A38: 3 | B38: Decision | C38: Is LCK format valid? | D38: AC005 | E38: LCK | F38: Valid/Invalid | G38: BR064 | H38: Yes: step 4 / No: error
A56: EXPECTED OUTPUTS
A57: # | B57: Output | C57: Status | D57: Owner | E57: Uploaded to BAForge | F57: Notes
A58: 1 | B58: Workflow catalogue (WF001-WFnnn)
A59: 2 | B59: Steps with type/description/actor/output
A60: 3 | B60: Trigger events
A61: 4 | B61: Decision points with branch logic
A64: ACTIONS & FOLLOW-UPS
...

Sheet T08 DataModel
A1: T08 Build Data Model
A2: Stage: Define | Step: Data Model | Category: Data Modelling | Tool: BAForge Agent > Data Model
A3: Goal: Define entities with field-level source-to-target mapping and migration status
A5: WORKSHOP LOGISTICS
A6: Date | E6: Duration | F6: 1-2 days per entity
A7: Facilitator | E7: Location / Link
A8: Workshop Type | B8: Data mapping with architects + source system owners | E8: Project
A10: ATTENDEES
A11: # | B11: Name | C11: Role | D11: Organisation | E11: Email | F11: Present (Y/N) | G11: Action Owner | H11: Notes
A12: 1
A13: 2
A14: 3
A15: 4
A16: 5
A17: 6
A19: PREPARATION CHECKLIST
A20: # | B20: Input Required | C20: Source | D20: Status | E20: Owner | F20: Notes
A21: 1 | B21: Source system schemas / data dictionaries | D21: Source DBA
A22: 2 | B22: Target system specs / API docs | D22: Target system team
A23: 3 | B23: Business rules (T06) | D23: T06 output
A24: 4 | B24: API response samples | D24: Integration team
A26: WORKSHOP CAPTURE
A27: Entity definition
A28: Entity ID | B28: ENT01
A29: Entity Name | B29: e.g. Legal Commitment (LCK)
A30: Source System | B30: e.g. Financial Hub / SUMMA
A31: Description | B31: What this entity represents...
A33: Field mapping
A34: Field Name | B34: Label | C34: Source Path | D34: Target Field | E34: Type | F34: Edit Mode | G34: Mandatory | H34: Migration Status
A35: local_key | B35: LCK Ref | C35: local_key | D35: lck_reference | E35: String | F35: Read | G35: Y | H35: ok
A36: notice_period | B36: Notice Period | C36: N/A | D36: notice_period | E36: Integer | F36: Edit | G36: N | H36: TBI
A58: Field details (per field requiring explanation)
A59: Field Name | B59: BR Reference | C59: Sample Value | D59: Compliance Note | E59: Transformation Rule | F59: Validation | G59: WF Usage | H59: Notes
A77: EXPECTED OUTPUTS
A78: # | B78: Output | C78: Status | D78: Owner | E78: Uploaded to BAForge | F78: Notes
A79: 1 | B79: Entity catalogue (ENT01-ENTnn)
A80: 2 | B80: Field mapping per entity
A81: 3 | B81: TBI/Gap field identification
A82: 4 | B82: Workflow-field usage matrix
A85: ACTIONS & FOLLOW-UPS
...

Sheet T09 APIs
A1: T10 Specify API Endpoints
A2: Stage: Define | Step: API Specs | Category: Integration | Tool: BAForge Agent > API Specs
A3: Goal: Document each API endpoint with method, path, entity, auth, call sequence, and error codes
A5: WORKSHOP LOGISTICS
A6: Date | E6: Duration | F6: Half day
A7: Facilitator | E7: Location / Link
A8: Workshop Type | B8: API review with integration team | E8: Project
A10: ATTENDEES
A11: # | B11: Name | C11: Role | D11: Organisation | E11: Email | F11: Present (Y/N) | G11: Action Owner | H11: Notes
A12: 1
A13: 2
A14: 3
A15: 4
A16: 5
A17: 6
A19: PREPARATION CHECKLIST
A20: # | B20: Input Required | C20: Source | D20: Status | E20: Owner | F20: Notes
A21: 1 | B21: API documentation / Swagger | D21: Source system API docs
A22: 2 | B22: Data model (T08) | D22: T08 output
A23: 3 | B23: Business rules (T06) | D23: T06 output
A24: 4 | B24: Security requirements | D24: Security team
A26: WORKSHOP CAPTURE
A27: Endpoint specification
A28: Endpoint ID | B28: EP01
A29: Method | B29: GET / POST / PUT / PATCH / DELETE
A30: Path | B30: /legal-commitments/{localKey}/last-validated
A31: Description | B31: Retrieve legal commitment data by local key
A32: Entity | B32: LCK
A33: Authentication | B33: OAuth 2.0 / API Key / mTLS
A34: Rate Limiting | B34: 100 req/min per client
A36: Call sequence
A37: Call sequence | B37: 1. Call with key 2. Extract sub-keys from response 3. Trigger parallel calls to EP02 + EP03
A39: Error codes
A40: HTTP Code | B40: Error Name | C40: Description | D40: Retry Strategy | E40: Fallback Action | F40: Linked BR
A41: 200 | B41: Success | C41: Data returned successfully | D41: N/A | E41: N/A
A42: 404 | B42: Not Found | C42: Entity not found with given key | D42: No retry | E42: Show user-friendly error per BR064 | F42: BR064
A53: EXPECTED OUTPUTS
A54: # | B54: Output | C54: Status | D54: Owner | E54: Uploaded to BAForge | F54: Notes
A55: 1 | B55: Endpoint catalogue (EP01-EPnn)
A56: 2 | B56: Method/path/description
...

Sheet T10 TechSpecs
A1: T11 Define Technical Specifications
A2: Stage: Execute | Step: Build | Category: Specification | Tool: BAForge Agent > Build
A3: Goal: Document tech stack, migration approach, testing strategy, audit controls, security, and reporting
A5: WORKSHOP LOGISTICS
A6: Date | E6: Duration | F6: Half day
A7: Facilitator | E7: Location / Link
A8: Workshop Type | B8: Technical design review | E8: Project
A10: ATTENDEES
A11: # | B11: Name | C11: Role | D11: Organisation | E11: Email | F11: Present (Y/N) | G11: Action Owner | H11: Notes
A12: 1
A13: 2
A14: 3
A15: 4
A16: 5
A17: 6
A19: PREPARATION CHECKLIST
A20: # | B20: Input Required | C20: Source | D20: Status | E20: Owner | F20: Notes
A21: 1 | B21: Data model (T08) | D21: T08 output
A22: 2 | B22: API specs (T10) | D22: T10 output
A23: 3 | B23: NFRs (T30) | D23: T30 output
A24: 4 | B24: Compliance assessment (T04) | D24: T04 output
A26: WORKSHOP CAPTURE
A27: Technology stack
A28: Layer | B28: Technology | C28: Version | D28: Purpose | E28: License | F28: Support Status | G28: Alternative Considered | H28: Decision Ref
A29: Frontend | B29: Java / Oracle | C29: 11 / 19c | D29: Application server + DB | E29: Oracle License | F29: Active | G29: PostgreSQL (rejected: Oracle mandated) | H29: DEC-001
A39: Testing strategy
A40: Test levels | B40: Unit > Integration > System > UAT > Performance > Security
A41: Test environments | B41: DEV > SIT > UAT > PRE-PROD > PROD
A42: UAT acceptance criteria | B42: All critical test cases pass, zero P1 defects, <5 P2...
A43: Test data strategy | B43: Anonymised production data / synthetic data / test data generators...
A45: Audit & security
A46: Audit trail requirements | B46: What changes must be logged, retention period, ISAE 3402...
A47: Authentication | B47: EU Login SSO / OAuth 2.0 / SAML / mTLS...
A48: Encryption | B48: At rest (AES-256), in transit (TLS 1.3), key management...
A51: EXPECTED OUTPUTS
A52: # | B52: Output | C52: Status | D52: Owner | E52: Uploaded to BAForge | F52: Notes
A53: 1 | B53: Technology stack decision
A54: 2 | B54: Data migration rules
A55: 3 | B55: Testing strategy and UAT criteria
A56: 4 | B56: Audit trail requirements
...

Sheet T11 Deploy
A1: T12 Plan Transition & Handover
A2: Stage: Execute | Step: Deploy | Category: Delivery | Tool: BAForge Agent > Deploy
A3: Goal: Define rollout strategy, training plan, handover deliverables, hypercare, and go-live criteria
A5: WORKSHOP LOGISTICS
A6: Date | E6: Duration | F6: Half day
A7: Facilitator | E7: Location / Link
A8: Workshop Type | B8: Transition planning with PMO + change management | E8: Project
A10: ATTENDEES
A11: # | B11: Name | C11: Role | D11: Organisation | E11: Email | F11: Present (Y/N) | G11: Action Owner | H11: Notes
A12: 1
A13: 2
A14: 3
A15: 4
A16: 5
A17: 6
A19: PREPARATION CHECKLIST
A20: # | B20: Input Required | C20: Source | D20: Status | E20: Owner | F20: Notes
A21: 1 | B21: Technical specs (T11) | D21: T11 output
A22: 2 | B22: Actor catalogue (T05) | D22: T05 output
A23: 3 | B23: Risk register (T27) | D23: T27 output
A24: 4 | B24: Data volumes (T31) | D24: T31 output
A26: WORKSHOP CAPTURE
A27: Rollout strategy
A28: Approach | B28: Phased by region / Big-bang / Parallel run / Pilot + rollout
A29: Phases / Waves | B29: Wave 1: 28 delegations (Western Europe), Wave 2: ...
A30: Rollback criteria | B30: If X then rollback: steps to revert to previous state...
A31: Data freeze window | B31: When does data entry stop before cutover? How long?
A33: Go-live checklist
A34: # | B34: Item | C34: Status | D34: Evidence / Notes
A35: 1 | B35: All critical UAT test cases passed
A36: 2 | B36: Zero P1 defects open
A37: 3 | B37: Data migration verified (100% match)
A38: 4 | B38: Rollback procedure tested
A39: 5 | B39: Training completed for all actor roles
A40: 6 | B40: Hypercare team on standby
A41: 7 | B41: Communication sent to all users
A42: 8 | B42: Monitoring and alerting configured
A43: 9 | B43: Sign-off from project sponsor
A44: 10 | B44: Sign-off from IT security
A46: Training plan
...

Sheet T12 Trace
A1: T15 Build Traceability Matrix
A2: Stage: Validate | Step: Traceability | Category: Quality | Tool: BAForge Agent > Traceability
A3: Goal: Map every requirement to user story, test case, and test steps — end-to-end trace
A5: WORKSHOP LOGISTICS
A6: Date | E6: Duration | F6: 2-3 hours
A7: Facilitator | E7: Location / Link
A8: Workshop Type | B8: Traceability review with QA lead and BA | E8: Project
A10: ATTENDEES
A11: # | B11: Name | C11: Role | D11: Organisation | E11: Email | F11: Present (Y/N) | G11: Action Owner | H11: Notes
A12: 1
A13: 2
A14: 3
A15: 4
A16: 5
A17: 6
A19: PREPARATION CHECKLIST
A20: # | B20: Input Required | C20: Source | D20: Status | E20: Owner | F20: Notes
A21: 1 | B21: Requirements (T03) | D21: T03 output
A22: 2 | B22: Business rules (T06) | D22: T06 output
A23: 3 | B23: User stories (T03) | D23: T03 output
A25: WORKSHOP CAPTURE
A26: Traceability matrix
A27: REQ ID | B27: Requirement | C27: User Story | D27: Test Case ID | E27: Test Steps (Given/When/Then) | F27: Priority | G27: Status | H27: Coverage
A28: REQ-001 | B28: Enforce valid status transitions | C28: As a DAS user I want... | D28: TC-001 | E28: Given DRAFT contract When set ARCHIVED Then error | F28: Critical | G28: Approved | H28: Full
A45: Coverage summary
A46: Total requirements
A47: Requirements with test cases
A48: Coverage %
A49: Gaps / untested requirements
A52: EXPECTED OUTPUTS
A53: # | B53: Output | C53: Status | D53: Owner | E53: Uploaded to BAForge | F53: Notes
A54: 1 | B54: Traceability items (REQ > US > TC > Test Steps)
A55: 2 | B55: Priority and status per trace
A56: 3 | B56: Coverage analysis
A59: ACTIONS & FOLLOW-UPS
A60: # | B60: Action | C60: Owner | D60: Due Date | E60: Priority | F60: Status | G60: Linked Task | H60: Notes
A71: CONNECTED TASKS (cross-reference)
A72: T03 | B72: Requirements are the source
A73: T06 | B73: Rules refine requirements
A74: T08 | B74: Field requirements are traced
...

Sheet T13 Risks
A1: T27 Maintain Risk Register
A2: Stage: Govern | Step: Governance | Category: Governance | Tool: BAForge Agent > Governance > Risks
A3: Goal: Identify, score (probability x impact), mitigate, and track project risks
A5: WORKSHOP LOGISTICS
A6: Date | E6: Duration | F6: 1-2 hours per review
A7: Facilitator | E7: Location / Link
A8: Workshop Type | B8: Risk review at each phase gate | E8: Project
A10: ATTENDEES
A11: # | B11: Name | C11: Role | D11: Organisation | E11: Email | F11: Present (Y/N) | G11: Action Owner | H11: Notes
A12: 1
A13: 2
A14: 3
A15: 4
A16: 5
A17: 6
A19: PREPARATION CHECKLIST
A20: # | B20: Input Required | C20: Source | D20: Status | E20: Owner | F20: Notes
A21: 1 | B21: Discovery findings (T02) | D21: T02 output
A22: 2 | B22: Compliance gaps (T04) | D22: T04 output
A23: 3 | B23: Open questions (T13) | D23: T13 output
A24: 4 | B24: Assumptions (T28) | D24: T28 output
A26: WORKSHOP CAPTURE
A27: Risk identification
A28: Risk ID | B28: Description | C28: Category | D28: Prob (1-5) | E28: Impact (1-5) | F28: Score | G28: Mitigation Plan | H28: Owner
A29: RSK-001 | B29: FH API structure differs from ABAC flat files | C29: Integration | D29: 4 | E29: 4 | F29: 16 | G29: Build adapter layer + validate mapping | H29: Integration Lead
A43: Risk scoring guide
A44: Score interpretation | B44: >=15 Critical (RED): Immediate escalation required 8-14 High (AMBER): Active mitigation, weekly review <=7 Low (GREEN): Monitor, monthly review
A47: EXPECTED OUTPUTS
A48: # | B48: Output | C48: Status | D48: Owner | E48: Uploaded to BAForge | F48: Notes
A49: 1 | B49: Risk register (RSK-001 to RSK-nnn)
A50: 2 | B50: Probability x Impact score
A51: 3 | B51: Mitigation plans
A52: 4 | B52: Risk owners and status
A53: 5 | B53: Linked requirements
A56: ACTIONS & FOLLOW-UPS
A57: # | B57: Action | C57: Owner | D57: Due Date | E57: Priority | F57: Status | G57: Linked Task | H57: Notes
A68: CONNECTED TASKS (cross-reference)
A69: T02 | B69: Discovery surfaces risks
A70: T04 | B70: Compliance gaps are regulatory risks
A71: T13 | B71: Unresolved questions are risks
...

Sheet T14 NFRs
A1: T30 Define Non-Functional Requirements
A2: Stage: Govern | Step: NFRs & Sizing | Category: Governance | Tool: BAForge Agent > NFRs & Sizing > NFRs
A3: Goal: Specify performance, availability, security, scalability, DR, and compliance targets
A5: WORKSHOP LOGISTICS
A6: Date | E6: Duration | F6: Half day
A7: Facilitator | E7: Location / Link
A8: Workshop Type | B8: NFR elicitation with architects + security + operations | E8: Project
A10: ATTENDEES
A11: # | B11: Name | C11: Role | D11: Organisation | E11: Email | F11: Present (Y/N) | G11: Action Owner | H11: Notes
A12: 1
A13: 2
A14: 3
A15: 4
A16: 5
A17: 6
A19: PREPARATION CHECKLIST
A20: # | B20: Input Required | C20: Source | D20: Status | E20: Owner | F20: Notes
A21: 1 | B21: Requirements (T03) | D21: T03 output
A22: 2 | B22: Compliance assessment (T04) | D22: T04 output
A23: 3 | B23: Data volumes (T31) | D23: T31 output
A24: 4 | B24: Existing SLAs | D24: Operations team
A26: WORKSHOP CAPTURE
A27: NFR catalogue
A28: NFR ID | B28: Category | C28: Requirement | D28: Metric | E28: Target | F28: Measurement Method | G28: Priority | H28: Entity
A29: NFR-001 | B29: Performance | C29: LCK pull must complete within 3s | D29: Response time (p95) | E29: < 3,000 ms | F29: APM monitoring + load test | G29: Critical | H29: LCK
A44: EXPECTED OUTPUTS
A45: # | B45: Output | C45: Status | D45: Owner | E45: Uploaded to BAForge | F45: Notes
A46: 1 | B46: NFR catalogue (NFR-001 to NFR-nnn)
A47: 2 | B47: Category, requirement, metric, target
A48: 3 | B48: Measurement method
A49: 4 | B49: Priority and linked entity
A52: ACTIONS & FOLLOW-UPS
A53: # | B53: Action | C53: Owner | D53: Due Date | E53: Priority | F53: Status | G53: Linked Task | H53: Notes
A64: CONNECTED TASKS (cross-reference)
A65: T03 | B65: Functional reqs have NFR counterparts
A66: T04 | B66: Compliance mandates specific NFRs
A67: T11 | B67: NFRs constrain tech specs
A68: T31 | B68: Volumes drive performance targets
A69: T23 | B69: NFRs export to Excel
A72: SFL Consulting | BAForge v3.1 | Workshop Template

Sheet T15 Volumes
A1: T31 Estimate Data Volumes
A2: Stage: Govern | Step: NFRs & Sizing | Category: Governance | Tool: BAForge Agent > NFRs & Sizing > Data Volumes
A3: Goal: Project data volumes, growth rates, concurrent users, API throughput, and storage per entity
A5: WORKSHOP LOGISTICS
A6: Date | E6: Duration | F6: 2-3 hours
A7: Facilitator | E7: Location / Link
A8: Workshop Type | B8: Sizing session with DBAs + architects | E8: Project
A10: ATTENDEES
A11: # | B11: Name | C11: Role | D11: Organisation | E11: Email | F11: Present (Y/N) | G11: Action Owner | H11: Notes
A12: 1
A13: 2
A14: 3
A15: 4
A16: 5
A17: 6
A19: PREPARATION CHECKLIST
A20: # | B20: Input Required | C20: Source | D20: Status | E20: Owner | F20: Notes
A21: 1 | B21: Data model entities (T08) | D21: T08 output
A22: 2 | B22: Production database stats | D22: DBA team
A23: 3 | B23: Business growth projections | D23: Business planning
A25: WORKSHOP CAPTURE
A26: Data volume estimates
A27: Entity | B27: Current Rows | C27: Growth %/yr | D27: Projected Go-Live | E27: Peak Users | F27: API Calls/Min | G27: Avg Record KB | H27: SLA Target
A28: Legal Commitments (LCK) | B28: 12,000 | C28: 8% | D28: 12,960 | E28: 200 | F28: 50 | G28: 4.2 KB | H28: < 3s (EP01)
A40: Infrastructure sizing
A41: Total storage estimate | B41: Sum of (projected rows x record size) across all entities
A42: Database sizing | B42: Primary + replica + backup retention requirements
A43: Network bandwidth | B43: Peak API traffic x average payload size
A44: Scaling strategy | B44: Horizontal / vertical / auto-scaling thresholds
A47: EXPECTED OUTPUTS
A48: # | B48: Output | C48: Status | D48: Owner | E48: Uploaded to BAForge | F48: Notes
A49: 1 | B49: Per entity: current rows, growth %, projected volume
A50: 2 | B50: Peak concurrent users
A51: 3 | B51: API calls/min at peak
A52: 4 | B52: Record size and total storage
A53: 5 | B53: SLA targets per entity
A56: ACTIONS & FOLLOW-UPS
A57: # | B57: Action | C57: Owner | D57: Due Date | E57: Priority | F57: Status | G57: Linked Task | H57: Notes
A68: CONNECTED TASKS (cross-reference)
A69: T08 | B69: Entities drive volume estimation
...

Sheet Export Actors
A1: Export: Actors
A2: Copy rows 5-16, paste into BAForge Agent > Business Logic > Actors > Import CSV
A3: Source: T05 Actors (rows 29+) | BAForge CSV layout: actors | Copy rows 5:16 → paste into BAForge CSV import
A4: ID | B4: Name | C4: Type | D4: Description | E4: CRUD | F4: Permissions
A5: ='T05 Actors'!A29 | B5: ='T05 Actors'!B29 | C5: ='T05 Actors'!C29 | D5: ='T05 Actors'!D29 | E5: ='T05 Actors'!E29&IF('T05 Actors'!F29="Y","R","")&IF('T05 Actors'!G29="Y","U","")&IF('T05 Actors'!H29="Y","D","")
A6: ='T05 Actors'!A30 | B6: ='T05 Actors'!B30 | C6: ='T05 Actors'!C30 | D6: ='T05 Actors'!D30 | E6: ='T05 Actors'!E30&IF('T05 Actors'!F30="Y","R","")&IF('T05 Actors'!G30="Y","U","")&IF('T05 Actors'!H30="Y","D","")
A7: ='T05 Actors'!A31 | B7: ='T05 Actors'!B31 | C7: ='T05 Actors'!C31 | D7: ='T05 Actors'!D31 | E7: ='T05 Actors'!E31&IF('T05 Actors'!F31="Y","R","")&IF('T05 Actors'!G31="Y","U","")&IF('T05 Actors'!H31="Y","D","")
A8: ='T05 Actors'!A32 | B8: ='T05 Actors'!B32 | C8: ='T05 Actors'!C32 | D8: ='T05 Actors'!D32 | E8: ='T05 Actors'!E32&IF('T05 Actors'!F32="Y","R","")&IF('T05 Actors'!G32="Y","U","")&IF('T05 Actors'!H32="Y","D","")
A9: ='T05 Actors'!A33 | B9: ='T05 Actors'!B33 | C9: ='T05 Actors'!C33 | D9: ='T05 Actors'!D33 | E9: ='T05 Actors'!E33&IF('T05 Actors'!F33="Y","R","")&IF('T05 Actors'!G33="Y","U","")&IF('T05 Actors'!H33="Y","D","")
A10: ='T05 Actors'!A34 | B10: ='T05 Actors'!B34 | C10: ='T05 Actors'!C34 | D10: ='T05 Actors'!D34 | E10: ='T05 Actors'!E34&IF('T05 Actors'!F34="Y","R","")&IF('T05 Actors'!G34="Y","U","")&IF('T05 Actors'!H34="Y","D","")
A11: ='T05 Actors'!A35 | B11: ='T05 Actors'!B35 | C11: ='T05 Actors'!C35 | D11: ='T05 Actors'!D35 | E11: ='T05 Actors'!E35&IF('T05 Actors'!F35="Y","R","")&IF('T05 Actors'!G35="Y","U","")&IF('T05 Actors'!H35="Y","D","")
A12: ='T05 Actors'!A36 | B12: ='T05 Actors'!B36 | C12: ='T05 Actors'!C36 | D12: ='T05 Actors'!D36 | E12: ='T05 Actors'!E36&IF('T05 Actors'!F36="Y","R","")&IF('T05 Actors'!G36="Y","U","")&IF('T05 Actors'!H36="Y","D","")
A13: ='T05 Actors'!A37 | B13: ='T05 Actors'!B37 | C13: ='T05 Actors'!C37 | D13: ='T05 Actors'!D37 | E13: ='T05 Actors'!E37&IF('T05 Actors'!F37="Y","R","")&IF('T05 Actors'!G37="Y","U","")&IF('T05 Actors'!H37="Y","D","")
A14: ='T05 Actors'!A38 | B14: ='T05 Actors'!B38 | C14: ='T05 Actors'!C38 | D14: ='T05 Actors'!D38 | E14: ='T05 Actors'!E38&IF('T05 Actors'!F38="Y","R","")&IF('T05 Actors'!G38="Y","U","")&IF('T05 Actors'!H38="Y","D","")
A15: ='T05 Actors'!A39 | B15: ='T05 Actors'!B39 | C15: ='T05 Actors'!C39 | D15: ='T05 Actors'!D39 | E15: ='T05 Actors'!E39&IF('T05 Actors'!F39="Y","R","")&IF('T05 Actors'!G39="Y","U","")&IF('T05 Actors'!H39="Y","D","")
A16: ='T05 Actors'!A40 | B16: ='T05 Actors'!B40 | C16: ='T05 Actors'!C40 | D16: ='T05 Actors'!D40 | E16: ='T05 Actors'!E40&IF('T05 Actors'!F40="Y","R","")&IF('T05 Actors'!G40="Y","U","")&IF('T05 Actors'!H40="Y","D","")
A19: COLUMN MAPPING
A20: CSV Column | B20: Source | C20: Description
A21: ID | B21: 'T05 Actors'!A | C21: Actor identifier (AC001 format)
A22: Name | B22: 'T05 Actors'!B | C22: Actor display name
A23: Type | B23: 'T05 Actors'!C | C23: Primary Actor / Secondary Actor / System Actor / External System / Timer/Scheduler
A24: Description | B24: 'T05 Actors'!D | C24: Role description
A25: CRUD | B25: Formula: ='T05 Actors'!E{r}&IF('T05 Actors'!F{r}="Y","R","")&IF('T05 Actors'!G{r}="Y","U","")&IF('T05 Actors'!H{r}="Y","D","") | C25: Concatenated CRUD string from individual C/R/U/D columns
A26: Permissions | B26: Manual entry | C26: Manual: permission scope description

Sheet Export Rules
A1: Export: Rules
A2: Copy rows 5-21, paste into BAForge Agent > Business Logic > Rules > Import CSV
A3: Source: T06 Rules (rows 29+) | BAForge CSV layout: rules | Copy rows 5:21 → paste into BAForge CSV import
A4: ID | B4: Name | C4: Category | D4: Priority | E4: Condition | F4: Action | G4: Exception | H4: Source | I4: RelatedReq
A5: ='T06 Rules'!A29 | B5: ='T06 Rules'!B29 | C5: ='T06 Rules'!C29 | D5: ='T06 Rules'!D29 | E5: ='T06 Rules'!E29 | F5: ='T06 Rules'!F29 | G5: ='T06 Rules'!G29 | H5: ='T06 Rules'!H29
A6: ='T06 Rules'!A30 | B6: ='T06 Rules'!B30 | C6: ='T06 Rules'!C30 | D6: ='T06 Rules'!D30 | E6: ='T06 Rules'!E30 | F6: ='T06 Rules'!F30 | G6: ='T06 Rules'!G30 | H6: ='T06 Rules'!H30
A7: ='T06 Rules'!A31 | B7: ='T06 Rules'!B31 | C7: ='T06 Rules'!C31 | D7: ='T06 Rules'!D31 | E7: ='T06 Rules'!E31 | F7: ='T06 Rules'!F31 | G7: ='T06 Rules'!G31 | H7: ='T06 Rules'!H31
A8: ='T06 Rules'!A32 | B8: ='T06 Rules'!B32 | C8: ='T06 Rules'!C32 | D8: ='T06 Rules'!D32 | E8: ='T06 Rules'!E32 | F8: ='T06 Rules'!F32 | G8: ='T06 Rules'!G32 | H8: ='T06 Rules'!H32
A9: ='T06 Rules'!A33 | B9: ='T06 Rules'!B33 | C9: ='T06 Rules'!C33 | D9: ='T06 Rules'!D33 | E9: ='T06 Rules'!E33 | F9: ='T06 Rules'!F33 | G9: ='T06 Rules'!G33 | H9: ='T06 Rules'!H33
A10: ='T06 Rules'!A34 | B10: ='T06 Rules'!B34 | C10: ='T06 Rules'!C34 | D10: ='T06 Rules'!D34 | E10: ='T06 Rules'!E34 | F10: ='T06 Rules'!F34 | G10: ='T06 Rules'!G34 | H10: ='T06 Rules'!H34
A11: ='T06 Rules'!A35 | B11: ='T06 Rules'!B35 | C11: ='T06 Rules'!C35 | D11: ='T06 Rules'!D35 | E11: ='T06 Rules'!E35 | F11: ='T06 Rules'!F35 | G11: ='T06 Rules'!G35 | H11: ='T06 Rules'!H35
A12: ='T06 Rules'!A36 | B12: ='T06 Rules'!B36 | C12: ='T06 Rules'!C36 | D12: ='T06 Rules'!D36 | E12: ='T06 Rules'!E36 | F12: ='T06 Rules'!F36 | G12: ='T06 Rules'!G36 | H12: ='T06 Rules'!H36
A13: ='T06 Rules'!A37 | B13: ='T06 Rules'!B37 | C13: ='T06 Rules'!C37 | D13: ='T06 Rules'!D37 | E13: ='T06 Rules'!E37 | F13: ='T06 Rules'!F37 | G13: ='T06 Rules'!G37 | H13: ='T06 Rules'!H37
A14: ='T06 Rules'!A38 | B14: ='T06 Rules'!B38 | C14: ='T06 Rules'!C38 | D14: ='T06 Rules'!D38 | E14: ='T06 Rules'!E38 | F14: ='T06 Rules'!F38 | G14: ='T06 Rules'!G38 | H14: ='T06 Rules'!H38
A15: ='T06 Rules'!A39 | B15: ='T06 Rules'!B39 | C15: ='T06 Rules'!C39 | D15: ='T06 Rules'!D39 | E15: ='T06 Rules'!E39 | F15: ='T06 Rules'!F39 | G15: ='T06 Rules'!G39 | H15: ='T06 Rules'!H39
A16: ='T06 Rules'!A40 | B16: ='T06 Rules'!B40 | C16: ='T06 Rules'!C40 | D16: ='T06 Rules'!D40 | E16: ='T06 Rules'!E40 | F16: ='T06 Rules'!F40 | G16: ='T06 Rules'!G40 | H16: ='T06 Rules'!H40
... A21: ='T06 Rules'!A45 | B21: ='T06 Rules'!B45 | C21: ='T06 Rules'!C45 | D21: ='T06 Rules'!D45 | E21: ='T06 Rules'!E45 | F21: ='T06 Rules'!F45 | G21: ='T06 Rules'!G45 | H21: ='T06 Rules'!H45
A24: COLUMN MAPPING
A25: CSV Column | B25: Source | C25: Description
A26: ID | B26: 'T06 Rules'!A | C26: Rule ID (BR001 format)
A27: Name | B27: 'T06 Rules'!B | C27: Rule name
A28: Category | B28: 'T06 Rules'!C | C28: Validation / Calculation / Authorization / Workflow / Data Quality / Compliance / Integration / Notification
A29: Priority | B29: 'T06 Rules'!D | C29: Critical / High / Medium / Low
A30: Condition | B30: 'T06 Rules'!E | C30: IF condition
A31: Action | B31: 'T06 Rules'!F | C31: THEN action
A32: Exception | B32: 'T06 Rules'!G | C32: ELSE exception
A33: Source | B33: 'T06 Rules'!H | C33: Source document or regulation
A34: RelatedReq | B34: Manual entry | C34: Manual: linked requirement ID (REQ-XXX)

Sheet Export Workflows
A1: Export: Workflows
A2: Copy rows 5-22, paste into BAForge Agent > Business Logic > Workflows > Import CSV. Note: WF_ID/Name/Trigger/Owner repeat for every step row.
A3: Source: T07 Workflows (rows 36+) | BAForge CSV layout: workflows | Copy rows 5:22 → paste into BAForge CSV import
A4: WF_ID | B4: Name | C4: Trigger | D4: Owner | E4: Step_Num | F4: Step_Type | G4: Step_Description | H4: Step_Actor | I4: Step_Output
A5: ='T07 Workflows'!='T07 Workflows'!B2736 | B5: ='T07 Workflows'!='T07 Workflows'!B2836 | C5: ='T07 Workflows'!='T07 Workflows'!B2936 | D5: ='T07 Workflows'!='T07 Workflows'!B3036 | E5: ='T07 Workflows'!A36 | F5: ='T07 Workflows'!B36 | G5: ='T07 Workflows'!C36 | H5: ='T07 Workflows'!D36
A6: ='T07 Workflows'!='T07 Workflows'!B2737 | B6: ='T07 Workflows'!='T07 Workflows'!B2837 | C6: ='T07 Workflows'!='T07 Workflows'!B2937 | D6: ='T07 Workflows'!='T07 Workflows'!B3037 | E6: ='T07 Workflows'!A37 | F6: ='T07 Workflows'!B37 | G6: ='T07 Workflows'!C37 | H6: ='T07 Workflows'!D37
A7: ='T07 Workflows'!='T07 Workflows'!B2738 | B7: ='T07 Workflows'!='T07 Workflows'!B2838 | C7: ='T07 Workflows'!='T07 Workflows'!B2938 | D7: ='T07 Workflows'!='T07 Workflows'!B3038 | E7: ='T07 Workflows'!A38 | F7: ='T07 Workflows'!B38 | G7: ='T07 Workflows'!C38 | H7: ='T07 Workflows'!D38
A8: ='T07 Workflows'!='T07 Workflows'!B2739 | B8: ='T07 Workflows'!='T07 Workflows'!B2839 | C8: ='T07 Workflows'!='T07 Workflows'!B2939 | D8: ='T07 Workflows'!='T07 Workflows'!B3039 | E8: ='T07 Workflows'!A39 | F8: ='T07 Workflows'!B39 | G8: ='T07 Workflows'!C39 | H8: ='T07 Workflows'!D39
A9: ='T07 Workflows'!='T07 Workflows'!B2740 | B9: ='T07 Workflows'!='T07 Workflows'!B2840 | C9: ='T07 Workflows'!='T07 Workflows'!B2940 | D9: ='T07 Workflows'!='T07 Workflows'!B3040 | E9: ='T07 Workflows'!A40 | F9: ='T07 Workflows'!B40 | G9: ='T07 Workflows'!C40 | H9: ='T07 Workflows'!D40
A10: ='T07 Workflows'!='T07 Workflows'!B2741 | B10: ='T07 Workflows'!='T07 Workflows'!B2841 | C10: ='T07 Workflows'!='T07 Workflows'!B2941 | D10: ='T07 Workflows'!='T07 Workflows'!B3041 | E10: ='T07 Workflows'!A41 | F10: ='T07 Workflows'!B41 | G10: ='T07 Workflows'!C41 | H10: ='T07 Workflows'!D41
A11: ='T07 Workflows'!='T07 Workflows'!B2742 | B11: ='T07 Workflows'!='T07 Workflows'!B2842 | C11: ='T07 Workflows'!='T07 Workflows'!B2942 | D11: ='T07 Workflows'!='T07 Workflows'!B3042 | E11: ='T07 Workflows'!A42 | F11: ='T07 Workflows'!B42 | G11: ='T07 Workflows'!C42 | H11: ='T07 Workflows'!D42
A12: ='T07 Workflows'!='T07 Workflows'!B2743 | B12: ='T07 Workflows'!='T07 Workflows'!B2843 | C12: ='T07 Workflows'!='T07 Workflows'!B2943 | D12: ='T07 Workflows'!='T07 Workflows'!B3043 | E12: ='T07 Workflows'!A43 | F12: ='T07 Workflows'!B43 | G12: ='T07 Workflows'!C43 | H12: ='T07 Workflows'!D43
A13: ='T07 Workflows'!='T07 Workflows'!B2744 | B13: ='T07 Workflows'!='T07 Workflows'!B2844 | C13: ='T07 Workflows'!='T07 Workflows'!B2944 | D13: ='T07 Workflows'!='T07 Workflows'!B3044 | E13: ='T07 Workflows'!A44 | F13: ='T07 Workflows'!B44 | G13: ='T07 Workflows'!C44 | H13: ='T07 Workflows'!D44
A14: ='T07 Workflows'!='T07 Workflows'!B2745 | B14: ='T07 Workflows'!='T07 Workflows'!B2845 | C14: ='T07 Workflows'!='T07 Workflows'!B2945 | D14: ='T07 Workflows'!='T07 Workflows'!B3045 | E14: ='T07 Workflows'!A45 | F14: ='T07 Workflows'!B45 | G14: ='T07 Workflows'!C45 | H14: ='T07 Workflows'!D45
A15: ='T07 Workflows'!='T07 Workflows'!B2746 | B15: ='T07 Workflows'!='T07 Workflows'!B2846 | C15: ='T07 Workflows'!='T07 Workflows'!B2946 | D15: ='T07 Workflows'!='T07 Workflows'!B3046 | E15: ='T07 Workflows'!A46 | F15: ='T07 Workflows'!B46 | G15: ='T07 Workflows'!C46 | H15: ='T07 Workflows'!D46
A16: ='T07 Workflows'!='T07 Workflows'!B2747 | B16: ='T07 Workflows'!='T07 Workflows'!B2847 | C16: ='T07 Workflows'!='T07 Workflows'!B2947 | D16: ='T07 Workflows'!='T07 Workflows'!B3047 | E16: ='T07 Workflows'!A47 | F16: ='T07 Workflows'!B47 | G16: ='T07 Workflows'!C47 | H16: ='T07 Workflows'!D47
... A22: ='T07 Workflows'!='T07 Workflows'!B2753 | B22: ='T07 Workflows'!='T07 Workflows'!B2853 | C22: ='T07 Workflows'!='T07 Workflows'!B2953 | D22: ='T07 Workflows'!='T07 Workflows'!B3053 | E22: ='T07 Workflows'!A53 | F22: ='T07 Workflows'!B53 | G22: ='T07 Workflows'!C53 | H22: ='T07 Workflows'!D53
A25: COLUMN MAPPING
A26: CSV Column | B26: Source | C26: Description
A27: WF_ID | B27: 'T07 Workflows'!='T07 Workflows'!B27 | C27: From workflow header (same for all steps in this WF)
A28: Name | B28: 'T07 Workflows'!='T07 Workflows'!B28 | C28: From workflow header Name field
A29: Trigger | B29: 'T07 Workflows'!='T07 Workflows'!B29 | C29: From workflow header Trigger field
A30: Owner | B30: 'T07 Workflows'!='T07 Workflows'!B30 | C30: From workflow header Owner field
A31: Step_Num | B31: 'T07 Workflows'!A | C31: Step number from steps table
A32: Step_Type | B32: 'T07 Workflows'!B | C32: Action / Decision / Subprocess / Start / End
A33: Step_Description | B33: 'T07 Workflows'!C | C33: Step description
A34: Step_Actor | B34: 'T07 Workflows'!D | C34: Actor performing this step
A35: Step_Output | B35: Manual entry | C35: Manual: step output — or use column F if captured

Sheet Export Fields
A1: Export: Fields
A2: Copy rows 5-26, paste into BAForge Agent > Data Model > (select entity) > Import CSV: Fields
A3: Source: T08 DataModel (rows 35+) | BAForge CSV layout: fields | Copy rows 5:26 → paste into BAForge CSV import
A4: Field_Name | B4: Label | C4: Source_Path | D4: Target_Field | E4: Data_Type | F4: Edit_Mode | G4: Mandatory | H4: BR_Ref | I4: Sample_Value | J4: Migration_Status | K4: Compliance_Note
A5: ='T08 DataModel'!A35 | B5: ='T08 DataModel'!B35 | C5: ='T08 DataModel'!C35 | D5: ='T08 DataModel'!D35 | E5: ='T08 DataModel'!E35 | F5: ='T08 DataModel'!F35 | G5: ='T08 DataModel'!G35 | H5: ='T08 DataModel'!H35
A6: ='T08 DataModel'!A36 | B6: ='T08 DataModel'!B36 | C6: ='T08 DataModel'!C36 | D6: ='T08 DataModel'!D36 | E6: ='T08 DataModel'!E36 | F6: ='T08 DataModel'!F36 | G6: ='T08 DataModel'!G36 | H6: ='T08 DataModel'!H36
A7: ='T08 DataModel'!A37 | B7: ='T08 DataModel'!B37 | C7: ='T08 DataModel'!C37 | D7: ='T08 DataModel'!D37 | E7: ='T08 DataModel'!E37 | F7: ='T08 DataModel'!F37 | G7: ='T08 DataModel'!G37 | H7: ='T08 DataModel'!H37
A8: ='T08 DataModel'!A38 | B8: ='T08 DataModel'!B38 | C8: ='T08 DataModel'!C38 | D8: ='T08 DataModel'!D38 | E8: ='T08 DataModel'!E38 | F8: ='T08 DataModel'!F38 | G8: ='T08 DataModel'!G38 | H8: ='T08 DataModel'!H38
A9: ='T08 DataModel'!A39 | B9: ='T08 DataModel'!B39 | C9: ='T08 DataModel'!C39 | D9: ='T08 DataModel'!D39 | E9: ='T08 DataModel'!E39 | F9: ='T08 DataModel'!F39 | G9: ='T08 DataModel'!G39 | H9: ='T08 DataModel'!H39
A10: ='T08 DataModel'!A40 | B10: ='T08 DataModel'!B40 | C10: ='T08 DataModel'!C40 | D10: ='T08 DataModel'!D40 | E10: ='T08 DataModel'!E40 | F10: ='T08 DataModel'!F40 | G10: ='T08 DataModel'!G40 | H10: ='T08 DataModel'!H40
A11: ='T08 DataModel'!A41 | B11: ='T08 DataModel'!B41 | C11: ='T08 DataModel'!C41 | D11: ='T08 DataModel'!D41 | E11: ='T08 DataModel'!E41 | F11: ='T08 DataModel'!F41 | G11: ='T08 DataModel'!G41 | H11: ='T08 DataModel'!H41
A12: ='T08 DataModel'!A42 | B12: ='T08 DataModel'!B42 | C12: ='T08 DataModel'!C42 | D12: ='T08 DataModel'!D42 | E12: ='T08 DataModel'!E42 | F12: ='T08 DataModel'!F42 | G12: ='T08 DataModel'!G42 | H12: ='T08 DataModel'!H42
A13: ='T08 DataModel'!A43 | B13: ='T08 DataModel'!B43 | C13: ='T08 DataModel'!C43 | D13: ='T08 DataModel'!D43 | E13: ='T08 DataModel'!E43 | F13: ='T08 DataModel'!F43 | G13: ='T08 DataModel'!G43 | H13: ='T08 DataModel'!H43
A14: ='T08 DataModel'!A44 | B14: ='T08 DataModel'!B44 | C14: ='T08 DataModel'!C44 | D14: ='T08 DataModel'!D44 | E14: ='T08 DataModel'!E44 | F14: ='T08 DataModel'!F44 | G14: ='T08 DataModel'!G44 | H14: ='T08 DataModel'!H44
A15: ='T08 DataModel'!A45 | B15: ='T08 DataModel'!B45 | C15: ='T08 DataModel'!C45 | D15: ='T08 DataModel'!D45 | E15: ='T08 DataModel'!E45 | F15: ='T08 DataModel'!F45 | G15: ='T08 DataModel'!G45 | H15: ='T08 DataModel'!H45
A16: ='T08 DataModel'!A46 | B16: ='T08 DataModel'!B46 | C16: ='T08 DataModel'!C46 | D16: ='T08 DataModel'!D46 | E16: ='T08 DataModel'!E46 | F16: ='T08 DataModel'!F46 | G16: ='T08 DataModel'!G46 | H16: ='T08 DataModel'!H46
... A26: ='T08 DataModel'!A56 | B26: ='T08 DataModel'!B56 | C26: ='T08 DataModel'!C56 | D26: ='T08 DataModel'!D56 | E26: ='T08 DataModel'!E56 | F26: ='T08 DataModel'!F56 | G26: ='T08 DataModel'!G56 | H26: ='T08 DataModel'!H56
A29: COLUMN MAPPING
A30: CSV Column | B30: Source | C30: Description
A31: Field_Name | B31: 'T08 DataModel'!A | C31: Technical field name
A32: Label | B32: 'T08 DataModel'!B | C32: Display label
A33: Source_Path | B33: 'T08 DataModel'!C | C33: Source system path (e.g. api.response.field)
A34: Target_Field | B34: 'T08 DataModel'!D | C34: Target system field name
A35: Data_Type | B35: 'T08 DataModel'!E | C35: String / Integer / Decimal / Boolean / Date / DateTime / Array / Object / Enum
A36: Edit_Mode | B36: 'T08 DataModel'!F | C36: Read / Edit / Auto / System / Calculated
A37: Mandatory | B37: 'T08 DataModel'!G | C37: Y or N
A38: Migration_Status | B38: 'T08 DataModel'!H | C38: ok / TBI / Gap / N/A / Partial / Deprecated
A39: Sample_Value | B39: Manual entry | C39: Manual: example value for this field
A40: BR_Ref | B40: Manual entry | C40: Manual: business rule reference (BR053)
A41: Compliance_Note | B41: Manual entry | C41: Manual: GDPR / regulatory note

Sheet Export Endpoints
A1: Export: Endpoints
A2: One row per endpoint. For multiple endpoints, fill one workshop sheet per EP, or consolidate manually here.
A3: Source: T09 APIs (rows 28+) | BAForge CSV layout: apiEndpoints | Copy rows 5:12 → paste into BAForge CSV import
A4: ID | B4: Method | C4: Path | D4: Description | E4: Entity | F4: Call_Sequence | G4: Rate_Limiting | H4: Request_Sample | I4: Response_Sample
A5: ='T09 APIs'!B28 | B5: ='T09 APIs'!='T09 APIs'!B2928 | C5: ='T09 APIs'!='T09 APIs'!B3028 | D5: ='T09 APIs'!='T09 APIs'!B3128 | E5: ='T09 APIs'!='T09 APIs'!B3228 | G5: ='T09 APIs'!='T09 APIs'!B3428
A6: ='T09 APIs'!B29 | B6: ='T09 APIs'!='T09 APIs'!B2929 | C6: ='T09 APIs'!='T09 APIs'!B3029 | D6: ='T09 APIs'!='T09 APIs'!B3129 | E6: ='T09 APIs'!='T09 APIs'!B3229 | G6: ='T09 APIs'!='T09 APIs'!B3429
A7: ='T09 APIs'!B30 | B7: ='T09 APIs'!='T09 APIs'!B2930 | C7: ='T09 APIs'!='T09 APIs'!B3030 | D7: ='T09 APIs'!='T09 APIs'!B3130 | E7: ='T09 APIs'!='T09 APIs'!B3230 | G7: ='T09 APIs'!='T09 APIs'!B3430
A8: ='T09 APIs'!B31 | B8: ='T09 APIs'!='T09 APIs'!B2931 | C8: ='T09 APIs'!='T09 APIs'!B3031 | D8: ='T09 APIs'!='T09 APIs'!B3131 | E8: ='T09 APIs'!='T09 APIs'!B3231 | G8: ='T09 APIs'!='T09 APIs'!B3431
A9: ='T09 APIs'!B32 | B9: ='T09 APIs'!='T09 APIs'!B2932 | C9: ='T09 APIs'!='T09 APIs'!B3032 | D9: ='T09 APIs'!='T09 APIs'!B3132 | E9: ='T09 APIs'!='T09 APIs'!B3232 | G9: ='T09 APIs'!='T09 APIs'!B3432
A10: ='T09 APIs'!B33 | B10: ='T09 APIs'!='T09 APIs'!B2933 | C10: ='T09 APIs'!='T09 APIs'!B3033 | D10: ='T09 APIs'!='T09 APIs'!B3133 | E10: ='T09 APIs'!='T09 APIs'!B3233 | G10: ='T09 APIs'!='T09 APIs'!B3433
A11: ='T09 APIs'!B34 | B11: ='T09 APIs'!='T09 APIs'!B2934 | C11: ='T09 APIs'!='T09 APIs'!B3034 | D11: ='T09 APIs'!='T09 APIs'!B3134 | E11: ='T09 APIs'!='T09 APIs'!B3234 | G11: ='T09 APIs'!='T09 APIs'!B3434
A12: ='T09 APIs'!B35 | B12: ='T09 APIs'!='T09 APIs'!B2935 | C12: ='T09 APIs'!='T09 APIs'!B3035 | D12: ='T09 APIs'!='T09 APIs'!B3135 | E12: ='T09 APIs'!='T09 APIs'!B3235 | G12: ='T09 APIs'!='T09 APIs'!B3435
A15: COLUMN MAPPING
A16: CSV Column | B16: Source | C16: Description
A17: ID | B17: 'T09 APIs'!B | C17: Endpoint ID from workshop capture
A18: Method | B18: 'T09 APIs'!='T09 APIs'!B29 | C18: HTTP method
A19: Path | B19: 'T09 APIs'!='T09 APIs'!B30 | C19: API path
A20: Description | B20: 'T09 APIs'!='T09 APIs'!B31 | C20: Endpoint description
A21: Entity | B21: 'T09 APIs'!='T09 APIs'!B32 | C21: Related entity
A22: Call_Sequence | B22: Manual entry | C22: Manual: copy from workshop call sequence field
A23: Rate_Limiting | B23: 'T09 APIs'!='T09 APIs'!B34 | C23: Rate limiting info
A24: Request_Sample | B24: Manual entry | C24: Manual: JSON request sample
A25: Response_Sample | B25: Manual entry | C25: Manual: JSON response sample

Sheet Export Requirements
A1: Export: Requirements
A2: Pulls REQ ID, text, and priority from T03 requirements table. Add user stories and test cases manually, then import into BAForge > Traceability.
A3: Source: T03 To-Be (rows 33+) | BAForge CSV layout: traceability | Copy rows 5:18 → paste into BAForge CSV import
A4: Req_ID | B4: Requirement | C4: User_Story | D4: Test_Case | E4: Test_Steps | F4: Priority | G4: Status
A5: ='T03 To-Be'!A33 | B5: ='T03 To-Be'!B33 | F5: ='T03 To-Be'!C33
A6: ='T03 To-Be'!A34 | B6: ='T03 To-Be'!B34 | F6: ='T03 To-Be'!C34
A7: ='T03 To-Be'!A35 | B7: ='T03 To-Be'!B35 | F7: ='T03 To-Be'!C35
A8: ='T03 To-Be'!A36 | B8: ='T03 To-Be'!B36 | F8: ='T03 To-Be'!C36
A9: ='T03 To-Be'!A37 | B9: ='T03 To-Be'!B37 | F9: ='T03 To-Be'!C37
A10: ='T03 To-Be'!A38 | B10: ='T03 To-Be'!B38 | F10: ='T03 To-Be'!C38
A11: ='T03 To-Be'!A39 | B11: ='T03 To-Be'!B39 | F11: ='T03 To-Be'!C39
A12: ='T03 To-Be'!A40 | B12: ='T03 To-Be'!B40 | F12: ='T03 To-Be'!C40
A13: ='T03 To-Be'!A41 | B13: ='T03 To-Be'!B41 | F13: ='T03 To-Be'!C41
A14: ='T03 To-Be'!A42 | B14: ='T03 To-Be'!B42 | F14: ='T03 To-Be'!C42
A15: ='T03 To-Be'!A43 | B15: ='T03 To-Be'!B43 | F15: ='T03 To-Be'!C43
A16: ='T03 To-Be'!A44 | B16: ='T03 To-Be'!B44 | F16: ='T03 To-Be'!C44
... A18: ='T03 To-Be'!A46 | B18: ='T03 To-Be'!B46 | F18: ='T03 To-Be'!C46
A21: COLUMN MAPPING
A22: CSV Column | B22: Source | C22: Description
A23: Req_ID | B23: 'T03 To-Be'!A | C23: Requirement ID (REQ-001 format)
A24: Requirement | B24: 'T03 To-Be'!B | C24: Requirement statement
A25: User_Story | B25: Manual entry | C25: Manual: As a [role] I want [capability] so that [benefit]
A26: Test_Case | B26: Manual entry | C26: Manual: Test case ID (TC-001)
A27: Test_Steps | B27: Manual entry | C27: Manual: Given/When/Then steps
A28: Priority | B28: 'T03 To-Be'!C | C28: Critical / High / Medium / Low — from workshop priority column
A29: Status | B29: Manual entry | C29: Manual: Draft / Approved / In Progress / Implemented / Tested

Sheet Export Questions
A1: Export: Questions
A2: Open questions emerge from multiple workshops (T02 discovery, T04 compliance, T08 data model TBI fields). Fill manually from workshop action items.
A3: Source: T08 DataModel (rows 35+) | BAForge CSV layout: openQuestions | Copy rows 5:16 → paste into BAForge CSV import
A4: ID | B4: Question | C4: Context | D4: Entity_Field | E4: Priority | F4: Status | G4: Assigned_To | H4: Answer
A19: COLUMN MAPPING
A20: CSV Column | B20: Source | C20: Description
A21: ID | B21: Manual entry | C21: Manual: Q001 format
A22: Question | B22: Manual entry | C22: Manual: the question text
A23: Context | B23: Manual entry | C23: Manual: why this question matters
A24: Entity_Field | B24: Manual entry | C24: Manual: Entity.field reference (e.g. LCK.notice_period)
A25: Priority | B25: Manual entry | C25: Critical / High / Medium / Low
A26: Status | B26: Manual entry | C26: Open / In Progress / Answered / Blocked / Closed
A27: Assigned_To | B27: Manual entry | C27: Manual: who should answer this
A28: Answer | B28: Manual entry | C28: Manual: resolution when answered

Sheet Export Glossary
A1: Export: Glossary
A2: Glossary terms emerge from all workshops. Collect terms as they come up, define in this sheet, import into BAForge > Open Items > Glossary.
A3: Source: T08 DataModel (rows 35+) | BAForge CSV layout: glossary | Copy rows 5:24 → paste into BAForge CSV import
A4: Term | B4: Definition | C4: Related_Entity
A27: COLUMN MAPPING
A28: CSV Column | B28: Source
A29: Term | B29: Manual entry | C29: Manual: domain term or acronym
A30: Definition | B30: Manual entry | C30: Manual: clear definition
A31: Related_Entity | B31: Manual entry | C31: Manual: linked entity name (LCK, LEF, BAF)

Sheet Export Risks
A1: Export: Risks
A2: Pulls risk data from T13 capture table. Score is calculated in BAForge (prob x impact). Import via agent Governance > Risks.
A3: Source: T13 Risks (rows 29+) | BAForge CSV layout: risks | Copy rows 5:18 → paste into BAForge CSV import
A4: Risk_ID | B4: Description | C4: Category | D4: Probability | E4: Impact | F4: Mitigation | G4: Owner | H4: Status | I4: Linked_REQ
A5: ='T13 Risks'!A29 | B5: ='T13 Risks'!B29 | C5: ='T13 Risks'!C29 | D5: ='T13 Risks'!D29 | E5: ='T13 Risks'!E29 | F5: ='T13 Risks'!G29 | G5: ='T13 Risks'!H29
A6: ='T13 Risks'!A30 | B6: ='T13 Risks'!B30 | C6: ='T13 Risks'!C30 | D6: ='T13 Risks'!D30 | E6: ='T13 Risks'!E30 | F6: ='T13 Risks'!G30 | G6: ='T13 Risks'!H30
A7: ='T13 Risks'!A31 | B7: ='T13 Risks'!B31 | C7: ='T13 Risks'!C31 | D7: ='T13 Risks'!D31 | E7: ='T13 Risks'!E31 | F7: ='T13 Risks'!G31 | G7: ='T13 Risks'!H31
A8: ='T13 Risks'!A32 | B8: ='T13 Risks'!B32 | C8: ='T13 Risks'!C32 | D8: ='T13 Risks'!D32 | E8: ='T13 Risks'!E32 | F8: ='T13 Risks'!G32 | G8: ='T13 Risks'!H32
A9: ='T13 Risks'!A33 | B9: ='T13 Risks'!B33 | C9: ='T13 Risks'!C33 | D9: ='T13 Risks'!D33 | E9: ='T13 Risks'!E33 | F9: ='T13 Risks'!G33 | G9: ='T13 Risks'!H33
A10: ='T13 Risks'!A34 | B10: ='T13 Risks'!B34 | C10: ='T13 Risks'!C34 | D10: ='T13 Risks'!D34 | E10: ='T13 Risks'!E34 | F10: ='T13 Risks'!G34 | G10: ='T13 Risks'!H34
A11: ='T13 Risks'!A35 | B11: ='T13 Risks'!B35 | C11: ='T13 Risks'!C35 | D11: ='T13 Risks'!D35 | E11: ='T13 Risks'!E35 | F11: ='T13 Risks'!G35 | G11: ='T13 Risks'!H35
